[2023-07-02T21:44:04.931+0530] {taskinstance.py:1103} INFO - Dependencies all met for dep_context=non-requeueable deps ti=<TaskInstance: load_data_dag.run_etl manual__2023-07-02T16:14:00.400287+00:00 [queued]>
[2023-07-02T21:44:04.936+0530] {taskinstance.py:1103} INFO - Dependencies all met for dep_context=requeueable deps ti=<TaskInstance: load_data_dag.run_etl manual__2023-07-02T16:14:00.400287+00:00 [queued]>
[2023-07-02T21:44:04.937+0530] {taskinstance.py:1308} INFO - Starting attempt 1 of 2
[2023-07-02T21:44:04.946+0530] {taskinstance.py:1327} INFO - Executing <Task(PythonOperator): run_etl> on 2023-07-02 16:14:00.400287+00:00
[2023-07-02T21:44:04.950+0530] {standard_task_runner.py:57} INFO - Started process 98924 to run task
[2023-07-02T21:44:04.956+0530] {standard_task_runner.py:84} INFO - Running: ['airflow', 'tasks', 'run', 'load_data_dag', 'run_etl', 'manual__2023-07-02T16:14:00.400287+00:00', '--job-id', '29', '--raw', '--subdir', 'DAGS_FOLDER/load_data_dag.py', '--cfg-path', '/var/folders/1q/9_fjtq3x20g5lbhb24f74l380000gn/T/tmp5_o4uhve']
[2023-07-02T21:44:04.959+0530] {standard_task_runner.py:85} INFO - Job 29: Subtask run_etl
[2023-07-02T21:44:05.002+0530] {task_command.py:410} INFO - Running <TaskInstance: load_data_dag.run_etl manual__2023-07-02T16:14:00.400287+00:00 [running]> on host shubhams-macbook-air.local
[2023-07-02T21:44:05.041+0530] {taskinstance.py:1545} INFO - Exporting env vars: AIRFLOW_CTX_DAG_EMAIL='your-email@example.com' AIRFLOW_CTX_DAG_OWNER='admin' AIRFLOW_CTX_DAG_ID='load_data_dag' AIRFLOW_CTX_TASK_ID='run_etl' AIRFLOW_CTX_EXECUTION_DATE='2023-07-02T16:14:00.400287+00:00' AIRFLOW_CTX_TRY_NUMBER='1' AIRFLOW_CTX_DAG_RUN_ID='manual__2023-07-02T16:14:00.400287+00:00'
[2023-07-02T21:44:05.043+0530] {taskinstance.py:1824} ERROR - Task failed with exception
Traceback (most recent call last):
  File "/Users/shubhampriyadarshi/PycharmProjects/PacktAPI/venv/lib/python3.11/site-packages/airflow/operators/python.py", line 181, in execute
    return_value = self.execute_callable()
                   ^^^^^^^^^^^^^^^^^^^^^^^
  File "/Users/shubhampriyadarshi/PycharmProjects/PacktAPI/venv/lib/python3.11/site-packages/airflow/operators/python.py", line 198, in execute_callable
    return self.python_callable(*self.op_args, **self.op_kwargs)
           ^^^^^^^^^^^^^^^^^^^^^^^^^^^^^^^^^^^^^^^^^^^^^^^^^^^^^
  File "/Users/shubhampriyadarshi/PycharmProjects/PacktAPI/airflow/dags/load_data_dag.py", line 26, in call_endpoint
    future = executor.submit(httpx.run, call_endpoint_async)
                             ^^^^^^^^^
AttributeError: module 'httpx' has no attribute 'run'
[2023-07-02T21:44:05.049+0530] {taskinstance.py:1345} INFO - Marking task as UP_FOR_RETRY. dag_id=load_data_dag, task_id=run_etl, execution_date=20230702T161400, start_date=20230702T161404, end_date=20230702T161405
[2023-07-02T21:44:05.054+0530] {standard_task_runner.py:104} ERROR - Failed to execute job 29 for task run_etl (module 'httpx' has no attribute 'run'; 98924)
[2023-07-02T21:44:05.063+0530] {local_task_job_runner.py:225} INFO - Task exited with return code 1
[2023-07-02T21:44:05.074+0530] {taskinstance.py:2653} INFO - 0 downstream tasks scheduled from follow-on schedule check
