[2023-07-04T21:21:01.365+0530] {taskinstance.py:1103} INFO - Dependencies all met for dep_context=non-requeueable deps ti=<TaskInstance: stackexchange_elt.dbt_curation manual__2023-07-04T15:50:49.010236+00:00 [queued]>
[2023-07-04T21:21:01.370+0530] {taskinstance.py:1103} INFO - Dependencies all met for dep_context=requeueable deps ti=<TaskInstance: stackexchange_elt.dbt_curation manual__2023-07-04T15:50:49.010236+00:00 [queued]>
[2023-07-04T21:21:01.370+0530] {taskinstance.py:1308} INFO - Starting attempt 1 of 2
[2023-07-04T21:21:01.377+0530] {taskinstance.py:1327} INFO - Executing <Task(PythonOperator): dbt_curation> on 2023-07-04 15:50:49.010236+00:00
[2023-07-04T21:21:01.381+0530] {standard_task_runner.py:57} INFO - Started process 12590 to run task
[2023-07-04T21:21:01.385+0530] {standard_task_runner.py:84} INFO - Running: ['airflow', 'tasks', 'run', 'stackexchange_elt', 'dbt_curation', 'manual__2023-07-04T15:50:49.010236+00:00', '--job-id', '53', '--raw', '--subdir', 'DAGS_FOLDER/load_data_dag.py', '--cfg-path', '/var/folders/1q/9_fjtq3x20g5lbhb24f74l380000gn/T/tmpx32e3fs9']
[2023-07-04T21:21:01.386+0530] {standard_task_runner.py:85} INFO - Job 53: Subtask dbt_curation
[2023-07-04T21:21:01.413+0530] {task_command.py:410} INFO - Running <TaskInstance: stackexchange_elt.dbt_curation manual__2023-07-04T15:50:49.010236+00:00 [running]> on host shubhams-macbook-air.local
[2023-07-04T21:21:01.436+0530] {taskinstance.py:1545} INFO - Exporting env vars: AIRFLOW_CTX_DAG_EMAIL='your-email@example.com' AIRFLOW_CTX_DAG_OWNER='admin' AIRFLOW_CTX_DAG_ID='stackexchange_elt' AIRFLOW_CTX_TASK_ID='dbt_curation' AIRFLOW_CTX_EXECUTION_DATE='2023-07-04T15:50:49.010236+00:00' AIRFLOW_CTX_TRY_NUMBER='1' AIRFLOW_CTX_DAG_RUN_ID='manual__2023-07-04T15:50:49.010236+00:00'
[2023-07-04T21:21:01.439+0530] {taskinstance.py:1824} ERROR - Task failed with exception
Traceback (most recent call last):
  File "/Users/shubhampriyadarshi/.pyenv/versions/3.9.16/lib/python3.9/site-packages/airflow/operators/python.py", line 181, in execute
    return_value = self.execute_callable()
  File "/Users/shubhampriyadarshi/.pyenv/versions/3.9.16/lib/python3.9/site-packages/airflow/operators/python.py", line 198, in execute_callable
    return self.python_callable(*self.op_args, **self.op_kwargs)
  File "/Users/shubhampriyadarshi/PycharmProjects/StackExchange_API_PKT/airflow/dags/load_data_dag.py", line 45, in run_dbt_command
    subprocess.check_call(command, shell=True, cwd=dbt_path)
  File "/Users/shubhampriyadarshi/.pyenv/versions/3.9.16/lib/python3.9/subprocess.py", line 368, in check_call
    retcode = call(*popenargs, **kwargs)
  File "/Users/shubhampriyadarshi/.pyenv/versions/3.9.16/lib/python3.9/subprocess.py", line 349, in call
    with Popen(*popenargs, **kwargs) as p:
  File "/Users/shubhampriyadarshi/.pyenv/versions/3.9.16/lib/python3.9/subprocess.py", line 951, in __init__
    self._execute_child(args, executable, preexec_fn, close_fds,
  File "/Users/shubhampriyadarshi/.pyenv/versions/3.9.16/lib/python3.9/subprocess.py", line 1821, in _execute_child
    raise child_exception_type(errno_num, err_msg, err_filename)
FileNotFoundError: [Errno 2] No such file or directory: '/path/to/dbt_se/'
[2023-07-04T21:21:01.446+0530] {taskinstance.py:1345} INFO - Marking task as UP_FOR_RETRY. dag_id=stackexchange_elt, task_id=dbt_curation, execution_date=20230704T155049, start_date=20230704T155101, end_date=20230704T155101
[2023-07-04T21:21:01.450+0530] {standard_task_runner.py:104} ERROR - Failed to execute job 53 for task dbt_curation ([Errno 2] No such file or directory: '/path/to/dbt_se/'; 12590)
[2023-07-04T21:21:01.462+0530] {local_task_job_runner.py:225} INFO - Task exited with return code 1
[2023-07-04T21:21:01.475+0530] {taskinstance.py:2653} INFO - 0 downstream tasks scheduled from follow-on schedule check
