[2023-07-04T21:26:04.871+0530] {taskinstance.py:1103} INFO - Dependencies all met for dep_context=non-requeueable deps ti=<TaskInstance: stackexchange_elt.dbt_curation manual__2023-07-04T15:50:49.010236+00:00 [queued]>
[2023-07-04T21:26:04.877+0530] {taskinstance.py:1103} INFO - Dependencies all met for dep_context=requeueable deps ti=<TaskInstance: stackexchange_elt.dbt_curation manual__2023-07-04T15:50:49.010236+00:00 [queued]>
[2023-07-04T21:26:04.878+0530] {taskinstance.py:1308} INFO - Starting attempt 2 of 2
[2023-07-04T21:26:04.888+0530] {taskinstance.py:1327} INFO - Executing <Task(PythonOperator): dbt_curation> on 2023-07-04 15:50:49.010236+00:00
[2023-07-04T21:26:04.892+0530] {standard_task_runner.py:57} INFO - Started process 13108 to run task
[2023-07-04T21:26:04.899+0530] {standard_task_runner.py:84} INFO - Running: ['airflow', 'tasks', 'run', 'stackexchange_elt', 'dbt_curation', 'manual__2023-07-04T15:50:49.010236+00:00', '--job-id', '57', '--raw', '--subdir', 'DAGS_FOLDER/load_data_dag.py', '--cfg-path', '/var/folders/1q/9_fjtq3x20g5lbhb24f74l380000gn/T/tmpo2pbno6h']
[2023-07-04T21:26:04.901+0530] {standard_task_runner.py:85} INFO - Job 57: Subtask dbt_curation
[2023-07-04T21:26:04.929+0530] {task_command.py:410} INFO - Running <TaskInstance: stackexchange_elt.dbt_curation manual__2023-07-04T15:50:49.010236+00:00 [running]> on host shubhams-macbook-air.local
[2023-07-04T21:26:04.956+0530] {taskinstance.py:1545} INFO - Exporting env vars: AIRFLOW_CTX_DAG_EMAIL='your-email@example.com' AIRFLOW_CTX_DAG_OWNER='admin' AIRFLOW_CTX_DAG_ID='stackexchange_elt' AIRFLOW_CTX_TASK_ID='dbt_curation' AIRFLOW_CTX_EXECUTION_DATE='2023-07-04T15:50:49.010236+00:00' AIRFLOW_CTX_TRY_NUMBER='2' AIRFLOW_CTX_DAG_RUN_ID='manual__2023-07-04T15:50:49.010236+00:00'
[2023-07-04T21:26:08.093+0530] {taskinstance.py:1824} ERROR - Task failed with exception
Traceback (most recent call last):
  File "/Users/shubhampriyadarshi/.pyenv/versions/3.9.16/lib/python3.9/site-packages/airflow/operators/python.py", line 181, in execute
    return_value = self.execute_callable()
  File "/Users/shubhampriyadarshi/.pyenv/versions/3.9.16/lib/python3.9/site-packages/airflow/operators/python.py", line 198, in execute_callable
    return self.python_callable(*self.op_args, **self.op_kwargs)
  File "/Users/shubhampriyadarshi/PycharmProjects/StackExchange_API_PKT/airflow/dags/load_data_dag.py", line 45, in run_dbt_command
    subprocess.check_call(command, shell=True, cwd=dbt_path)
  File "/Users/shubhampriyadarshi/.pyenv/versions/3.9.16/lib/python3.9/subprocess.py", line 373, in check_call
    raise CalledProcessError(retcode, cmd)
subprocess.CalledProcessError: Command 'dbt run --models tag:curation --profiles-dir .' returned non-zero exit status 2.
[2023-07-04T21:26:08.101+0530] {taskinstance.py:1345} INFO - Marking task as FAILED. dag_id=stackexchange_elt, task_id=dbt_curation, execution_date=20230704T155049, start_date=20230704T155604, end_date=20230704T155608
[2023-07-04T21:26:08.108+0530] {standard_task_runner.py:104} ERROR - Failed to execute job 57 for task dbt_curation (Command 'dbt run --models tag:curation --profiles-dir .' returned non-zero exit status 2.; 13108)
[2023-07-04T21:26:08.149+0530] {local_task_job_runner.py:225} INFO - Task exited with return code 1
[2023-07-04T21:26:08.163+0530] {taskinstance.py:2653} INFO - 0 downstream tasks scheduled from follow-on schedule check
